Workbook

Sheet 2칸
A1: =Date!Q1&"님 ("&Date!R1&"세, "&Date!S1&") 보험 보장 분석" -> 님 (세, ) 보험 보장 분석
H2: (만원)
A3: 납입기간 / 만기 | F3: =IF(Date!F3="","",Date!F3) | G3: =IF(Date!G3="","",Date!G3)
A4: 보험회사 | F4: =IF(Date!F4="","",Date!F4) | G4: =IF(Date!G4="","",Date!G4)
A5: 상품명 | F5: =IF(Date!F5="","",Date!F5) | G5: =IF(Date!G5="","",Date!G5)
A6: 가입년도 | F6: =IF(Date!F6="","",Date!F6) | G6: =IF(Date!G6="","",Date!G6)
A7: 납입보험료 | F7: =IF(Date!F7="","",Date!F7) | G7: =IF(Date!G7="","",Date!G7)
A8: 사망 | D8: 일반사망 | F8: =IF(Date!F8="","",Date!F8) | G8: =IF(Date!G8="","",Date!G8)
D9: 상해사망 | F9: =IF(Date!F9="","",Date!F9) | G9: =IF(Date!G9="","",Date!G9)
D10: 질병사망 | F10: =IF(Date!F10="","",Date!F10) | G10: =IF(Date!G10="","",Date!G10)
A11: 후유 장해 | D11: 상해 3%~ | F11: =IF(Date!F11="","",Date!F11) | G11: =IF(Date!G11="","",Date!G11)
D12: 질병 3%~ | F12: =IF(Date!F12="","",Date!F12) | G12: =IF(Date!G12="","",Date!G12)
A13: 3대 진단 · 수술 | C13: 암 | D13: 고액암 | F13: =IF(Date!F13="","",Date!F13) | G13: =IF(Date!G13="","",Date!G13)
D14: 일반암 | F14: =IF(Date!F14="","",Date!F14) | G14: =IF(Date!G14="","",Date!G14)
D15: 유사암(갑,기,경,제) | F15: =IF(Date!F15="","",Date!F15) | G15: =IF(Date!G15="","",Date!G15)
D16: 재진단암 / 전이암 | F16: =IF(Date!F16="","",Date!F16) | G16: =IF(Date!G16="","",Date!G16)
D17: 항암 방사선 / 약물 | F17: =IF(Date!F17="","",Date!F17) | G17: =IF(Date!G17="","",Date!G17)
D18: 암수술비 | F18: =IF(Date!F18="","",Date!F18) | G18: =IF(Date!G18="","",Date!G18)
D19: 암중환자 | F19: =IF(Date!F19="","",Date!F19) | G19: =IF(Date!G19="","",Date!G19)
D20: 표적항암 / 카티 | F20: =IF(Date!F20="","",Date!F20) | G20: =IF(Date!G20="","",Date!G20)
D21: 암특정치료비 | F21: =IF(Date!F21="","",Date!F21) | G21: =IF(Date!G21="","",Date!G21)
C22: 뇌 | D22: 뇌경색 / 뇌출혈 진단 | F22: =IF(Date!F22="","",Date!F22) | G22: =IF(Date!G22="","",Date!G22)
D23: 뇌졸중 진단 | F23: =IF(Date!F23="","",Date!F23) | G23: =IF(Date!G23="","",Date!G23)
D24: 뇌혈관 진단 | F24: =IF(Date!F24="","",Date!F24) | G24: =IF(Date!G24="","",Date!G24)
D25: 뇌혈관 수술 | F25: =IF(Date!F25="","",Date!F25) | G25: =IF(Date!G25="","",Date!G25)
C26: 심장 | D26: 급성심근경색 진단 | F26: =IF(Date!F26="","",Date!F26) | G26: =IF(Date!G26="","",Date!G26)
D27: 심혈관 진단 | F27: =IF(Date!F27="","",Date!F27) | G27: =IF(Date!G27="","",Date!G27)
D28: 심혈관 수술 | F28: =IF(Date!F28="","",Date!F28) | G28: =IF(Date!G28="","",Date!G28)
A29: 산정특례 | D29: 1회 | F29: =IF(Date!F29="","",Date!F29) | G29: =IF(Date!G29="","",Date!G29)
D30: 년 1회 | F30: =IF(Date!F30="","",Date!F30) | G30: =IF(Date!G30="","",Date!G30)
A31: 수술 | C31: 상해 | D31: 상해 수술 | F31: =IF(Date!F31="","",Date!F31) | G31: =IF(Date!G31="","",Date!G31)
D32: 상해(1~5)종 수술 | F32: =IF(Date!F32="","",Date!F32) | G32: =IF(Date!G32="","",Date!G32)
C33: 질병 | D33: 질병 수술 | F33: =IF(Date!F33="","",Date!F33) | G33: =IF(Date!G33="","",Date!G33)
D34: 질병(1~5)종 수술 | F34: =IF(Date!F34="","",Date!F34) | G34: =IF(Date!G34="","",Date!G34)
D35: 대 수술 | F35: =IF(Date!F35="","",Date!F35) | G35: =IF(Date!G35="","",Date!G35)
D36: 대 수술 | F36: =IF(Date!F36="","",Date!F36) | G36: =IF(Date!G36="","",Date!G36)
A37: 입원 일당 | D37: 상해 입원 | F37: =IF(Date!F37="","",Date!F37) | G37: =IF(Date!G37="","",Date!G37)
D38: 질병 입원 | F38: =IF(Date!F38="","",Date!F38) | G38: =IF(Date!G38="","",Date!G38)
D39: 1인실 | F39: =IF(Date!F39="","",Date!F39) | G39: =IF(Date!G39="","",Date!G39)
D40: 2~3인실 | F40: =IF(Date!F40="","",Date!F40) | G40: =IF(Date!G40="","",Date!G40)
...

Sheet 3칸
A1: =Date!Q1&"님 ("&Date!R1&"세, "&Date!S1&") 보험 보장 분석" -> 님 (세, ) 보험 보장 분석
I2: (만원)
A3: 납입기간 / 만기 | F3: =IF(Date!F3="","",Date!F3) | G3: =IF(Date!G3="","",Date!G3) | H3: =IF(Date!H3="","",Date!H3)
A4: 보험회사 | F4: =IF(Date!F4="","",Date!F4) | G4: =IF(Date!G4="","",Date!G4) | H4: =IF(Date!H4="","",Date!H4)
A5: 상품명 | F5: =IF(Date!F5="","",Date!F5) | G5: =IF(Date!G5="","",Date!G5) | H5: =IF(Date!H5="","",Date!H5)
A6: 가입년도 | F6: =IF(Date!F6="","",Date!F6) | G6: =IF(Date!G6="","",Date!G6) | H6: =IF(Date!H6="","",Date!H6)
A7: 납입보험료 | F7: =IF(Date!F7="","",Date!F7) | G7: =IF(Date!G7="","",Date!G7) | H7: =IF(Date!H7="","",Date!H7)
A8: 사망 | D8: 일반사망 | F8: =IF(Date!F8="","",Date!F8) | G8: =IF(Date!G8="","",Date!G8) | H8: =IF(Date!H8="","",Date!H8)
D9: 상해사망 | F9: =IF(Date!F9="","",Date!F9) | G9: =IF(Date!G9="","",Date!G9) | H9: =IF(Date!H9="","",Date!H9)
D10: 질병사망 | F10: =IF(Date!F10="","",Date!F10) | G10: =IF(Date!G10="","",Date!G10) | H10: =IF(Date!H10="","",Date!H10)
A11: 후유 장해 | D11: 상해 3%~ | F11: =IF(Date!F11="","",Date!F11) | G11: =IF(Date!G11="","",Date!G11) | H11: =IF(Date!H11="","",Date!H11)
D12: 질병 3%~ | F12: =IF(Date!F12="","",Date!F12) | G12: =IF(Date!G12="","",Date!G12) | H12: =IF(Date!H12="","",Date!H12)
A13: 3대 진단 · 수술 | C13: 암 | D13: 고액암 | F13: =IF(Date!F13="","",Date!F13) | G13: =IF(Date!G13="","",Date!G13) | H13: =IF(Date!H13="","",Date!H13)
D14: 일반암 | F14: =IF(Date!F14="","",Date!F14) | G14: =IF(Date!G14="","",Date!G14) | H14: =IF(Date!H14="","",Date!H14)
D15: 유사암(갑,기,경,제) | F15: =IF(Date!F15="","",Date!F15) | G15: =IF(Date!G15="","",Date!G15) | H15: =IF(Date!H15="","",Date!H15)
D16: 재진단암 / 전이암 | F16: =IF(Date!F16="","",Date!F16) | G16: =IF(Date!G16="","",Date!G16) | H16: =IF(Date!H16="","",Date!H16)
D17: 항암 방사선 / 약물 | F17: =IF(Date!F17="","",Date!F17) | G17: =IF(Date!G17="","",Date!G17) | H17: =IF(Date!H17="","",Date!H17)
D18: 암수술비 | F18: =IF(Date!F18="","",Date!F18) | G18: =IF(Date!G18="","",Date!G18) | H18: =IF(Date!H18="","",Date!H18)
D19: 암중환자 | F19: =IF(Date!F19="","",Date!F19) | G19: =IF(Date!G19="","",Date!G19) | H19: =IF(Date!H19="","",Date!H19)
D20: 표적항암 / 카티 | F20: =IF(Date!F20="","",Date!F20) | G20: =IF(Date!G20="","",Date!G20) | H20: =IF(Date!H20="","",Date!H20)
D21: 암특정치료비 | F21: =IF(Date!F21="","",Date!F21) | G21: =IF(Date!G21="","",Date!G21) | H21: =IF(Date!H21="","",Date!H21)
C22: 뇌 | D22: 뇌경색 / 뇌출혈 진단 | F22: =IF(Date!F22="","",Date!F22) | G22: =IF(Date!G22="","",Date!G22) | H22: =IF(Date!H22="","",Date!H22)
D23: 뇌졸중 진단 | F23: =IF(Date!F23="","",Date!F23) | G23: =IF(Date!G23="","",Date!G23) | H23: =IF(Date!H23="","",Date!H23)
D24: 뇌혈관 진단 | F24: =IF(Date!F24="","",Date!F24) | G24: =IF(Date!G24="","",Date!G24) | H24: =IF(Date!H24="","",Date!H24)
D25: 뇌혈관 수술 | F25: =IF(Date!F25="","",Date!F25) | G25: =IF(Date!G25="","",Date!G25) | H25: =IF(Date!H25="","",Date!H25)
C26: 심장 | D26: 급성심근경색 진단 | F26: =IF(Date!F26="","",Date!F26) | G26: =IF(Date!G26="","",Date!G26) | H26: =IF(Date!H26="","",Date!H26)
D27: 심혈관 진단 | F27: =IF(Date!F27="","",Date!F27) | G27: =IF(Date!G27="","",Date!G27) | H27: =IF(Date!H27="","",Date!H27)
D28: 심혈관 수술 | F28: =IF(Date!F28="","",Date!F28) | G28: =IF(Date!G28="","",Date!G28) | H28: =IF(Date!H28="","",Date!H28)
A29: 산정특례 | D29: 1회 | F29: =IF(Date!F29="","",Date!F29) | G29: =IF(Date!G29="","",Date!G29) | H29: =IF(Date!H29="","",Date!H29)
D30: 년 1회 | F30: =IF(Date!F30="","",Date!F30) | G30: =IF(Date!G30="","",Date!G30) | H30: =IF(Date!H30="","",Date!H30)
A31: 수술 | C31: 상해 | D31: 상해 수술 | F31: =IF(Date!F31="","",Date!F31) | G31: =IF(Date!G31="","",Date!G31) | H31: =IF(Date!H31="","",Date!H31)
D32: 상해(1~5)종 수술 | F32: =IF(Date!F32="","",Date!F32) | G32: =IF(Date!G32="","",Date!G32) | H32: =IF(Date!H32="","",Date!H32)
C33: 질병 | D33: 질병 수술 | F33: =IF(Date!F33="","",Date!F33) | G33: =IF(Date!G33="","",Date!G33) | H33: =IF(Date!H33="","",Date!H33)
D34: 질병(1~5)종 수술 | F34: =IF(Date!F34="","",Date!F34) | G34: =IF(Date!G34="","",Date!G34) | H34: =IF(Date!H34="","",Date!H34)
D35: 대 수술 | F35: =IF(Date!F35="","",Date!F35) | G35: =IF(Date!G35="","",Date!G35) | H35: =IF(Date!H35="","",Date!H35)
D36: 대 수술 | F36: =IF(Date!F36="","",Date!F36) | G36: =IF(Date!G36="","",Date!G36) | H36: =IF(Date!H36="","",Date!H36)
A37: 입원 일당 | D37: 상해 입원 | F37: =IF(Date!F37="","",Date!F37) | G37: =IF(Date!G37="","",Date!G37) | H37: =IF(Date!H37="","",Date!H37)
D38: 질병 입원 | F38: =IF(Date!F38="","",Date!F38) | G38: =IF(Date!G38="","",Date!G38) | H38: =IF(Date!H38="","",Date!H38)
D39: 1인실 | F39: =IF(Date!F39="","",Date!F39) | G39: =IF(Date!G39="","",Date!G39) | H39: =IF(Date!H39="","",Date!H39)
D40: 2~3인실 | F40: =IF(Date!F40="","",Date!F40) | G40: =IF(Date!G40="","",Date!G40) | H40: =IF(Date!H40="","",Date!H40)
...

Sheet 4칸
A1: =Date!Q1&"님 ("&Date!R1&"세, "&Date!S1&") 보험 보장 분석" -> 님 (세, ) 보험 보장 분석
A2: ] | J2: (만원)
A3: 납입기간 / 만기 | F3: =IF(Date!F3="","",Date!F3) | G3: =IF(Date!G3="","",Date!G3) | H3: =IF(Date!H3="","",Date!H3) | I3: =IF(Date!I3="","",Date!I3)
A4: 보험회사 | F4: =IF(Date!F4="","",Date!F4) | G4: =IF(Date!G4="","",Date!G4) | H4: =IF(Date!H4="","",Date!H4) | I4: =IF(Date!I4="","",Date!I4)
A5: 상품명 | F5: =IF(Date!F5="","",Date!F5) | G5: =IF(Date!G5="","",Date!G5) | H5: =IF(Date!H5="","",Date!H5) | I5: =IF(Date!I5="","",Date!I5)
A6: 가입년도 | F6: =IF(Date!F6="","",Date!F6) | G6: =IF(Date!G6="","",Date!G6) | H6: =IF(Date!H6="","",Date!H6) | I6: =IF(Date!I6="","",Date!I6)
A7: 납입보험료 | F7: =IF(Date!F7="","",Date!F7) | G7: =IF(Date!G7="","",Date!G7) | H7: =IF(Date!H7="","",Date!H7) | I7: =IF(Date!I7="","",Date!I7)
A8: 사망 | D8: 일반사망 | F8: =IF(Date!F8="","",Date!F8) | G8: =IF(Date!G8="","",Date!G8) | H8: =IF(Date!H8="","",Date!H8) | I8: =IF(Date!I8="","",Date!I8)
D9: 상해사망 | F9: =IF(Date!F9="","",Date!F9) | G9: =IF(Date!G9="","",Date!G9) | H9: =IF(Date!H9="","",Date!H9) | I9: =IF(Date!I9="","",Date!I9)
D10: 질병사망 | F10: =IF(Date!F10="","",Date!F10) | G10: =IF(Date!G10="","",Date!G10) | H10: =IF(Date!H10="","",Date!H10) | I10: =IF(Date!I10="","",Date!I10)
A11: 후유 장해 | D11: 상해 3%~ | F11: =IF(Date!F11="","",Date!F11) | G11: =IF(Date!G11="","",Date!G11) | H11: =IF(Date!H11="","",Date!H11) | I11: =IF(Date!I11="","",Date!I11)
D12: 질병 3%~ | F12: =IF(Date!F12="","",Date!F12) | G12: =IF(Date!G12="","",Date!G12) | H12: =IF(Date!H12="","",Date!H12) | I12: =IF(Date!I12="","",Date!I12)
A13: 3대 진단 · 수술 | C13: 암 | D13: 고액암 | F13: =IF(Date!F13="","",Date!F13) | G13: =IF(Date!G13="","",Date!G13) | H13: =IF(Date!H13="","",Date!H13) | I13: =IF(Date!I13="","",Date!I13)
D14: 일반암 | F14: =IF(Date!F14="","",Date!F14) | G14: =IF(Date!G14="","",Date!G14) | H14: =IF(Date!H14="","",Date!H14) | I14: =IF(Date!I14="","",Date!I14)
D15: 유사암(갑,기,경,제) | F15: =IF(Date!F15="","",Date!F15) | G15: =IF(Date!G15="","",Date!G15) | H15: =IF(Date!H15="","",Date!H15) | I15: =IF(Date!I15="","",Date!I15)
D16: 재진단암 / 전이암 | F16: =IF(Date!F16="","",Date!F16) | G16: =IF(Date!G16="","",Date!G16) | H16: =IF(Date!H16="","",Date!H16) | I16: =IF(Date!I16="","",Date!I16)
D17: 항암 방사선 / 약물 | F17: =IF(Date!F17="","",Date!F17) | G17: =IF(Date!G17="","",Date!G17) | H17: =IF(Date!H17="","",Date!H17) | I17: =IF(Date!I17="","",Date!I17)
D18: 암수술비 | F18: =IF(Date!F18="","",Date!F18) | G18: =IF(Date!G18="","",Date!G18) | H18: =IF(Date!H18="","",Date!H18) | I18: =IF(Date!I18="","",Date!I18)
D19: 암중환자 | F19: =IF(Date!F19="","",Date!F19) | G19: =IF(Date!G19="","",Date!G19) | H19: =IF(Date!H19="","",Date!H19) | I19: =IF(Date!I19="","",Date!I19)
D20: 표적항암 / 카티 | F20: =IF(Date!F20="","",Date!F20) | G20: =IF(Date!G20="","",Date!G20) | H20: =IF(Date!H20="","",Date!H20) | I20: =IF(Date!I20="","",Date!I20)
D21: 암특정치료비 | F21: =IF(Date!F21="","",Date!F21) | G21: =IF(Date!G21="","",Date!G21) | H21: =IF(Date!H21="","",Date!H21) | I21: =IF(Date!I21="","",Date!I21)
C22: 뇌 | D22: 뇌경색 / 뇌출혈 진단 | F22: =IF(Date!F22="","",Date!F22) | G22: =IF(Date!G22="","",Date!G22) | H22: =IF(Date!H22="","",Date!H22) | I22: =IF(Date!I22="","",Date!I22)
D23: 뇌졸중 진단 | F23: =IF(Date!F23="","",Date!F23) | G23: =IF(Date!G23="","",Date!G23) | H23: =IF(Date!H23="","",Date!H23) | I23: =IF(Date!I23="","",Date!I23)
D24: 뇌혈관 진단 | F24: =IF(Date!F24="","",Date!F24) | G24: =IF(Date!G24="","",Date!G24) | H24: =IF(Date!H24="","",Date!H24) | I24: =IF(Date!I24="","",Date!I24)
D25: 뇌혈관 수술 | F25: =IF(Date!F25="","",Date!F25) | G25: =IF(Date!G25="","",Date!G25) | H25: =IF(Date!H25="","",Date!H25) | I25: =IF(Date!I25="","",Date!I25)
C26: 심장 | D26: 급성심근경색 진단 | F26: =IF(Date!F26="","",Date!F26) | G26: =IF(Date!G26="","",Date!G26) | H26: =IF(Date!H26="","",Date!H26) | I26: =IF(Date!I26="","",Date!I26)
D27: 심혈관 진단 | F27: =IF(Date!F27="","",Date!F27) | G27: =IF(Date!G27="","",Date!G27) | H27: =IF(Date!H27="","",Date!H27) | I27: =IF(Date!I27="","",Date!I27)
D28: 심혈관 수술 | F28: =IF(Date!F28="","",Date!F28) | G28: =IF(Date!G28="","",Date!G28) | H28: =IF(Date!H28="","",Date!H28) | I28: =IF(Date!I28="","",Date!I28)
A29: 산정특례 | D29: 1회 | F29: =IF(Date!F29="","",Date!F29) | G29: =IF(Date!G29="","",Date!G29) | H29: =IF(Date!H29="","",Date!H29) | I29: =IF(Date!I29="","",Date!I29)
D30: 년 1회 | F30: =IF(Date!F30="","",Date!F30) | G30: =IF(Date!G30="","",Date!G30) | H30: =IF(Date!H30="","",Date!H30) | I30: =IF(Date!I30="","",Date!I30)
A31: 수술 | C31: 상해 | D31: 상해 수술 | F31: =IF(Date!F31="","",Date!F31) | G31: =IF(Date!G31="","",Date!G31) | H31: =IF(Date!H31="","",Date!H31) | I31: =IF(Date!I31="","",Date!I31)
D32: 상해(1~5)종 수술 | F32: =IF(Date!F32="","",Date!F32) | G32: =IF(Date!G32="","",Date!G32) | H32: =IF(Date!H32="","",Date!H32) | I32: =IF(Date!I32="","",Date!I32)
C33: 질병 | D33: 질병 수술 | F33: =IF(Date!F33="","",Date!F33) | G33: =IF(Date!G33="","",Date!G33) | H33: =IF(Date!H33="","",Date!H33) | I33: =IF(Date!I33="","",Date!I33)
D34: 질병(1~5)종 수술 | F34: =IF(Date!F34="","",Date!F34) | G34: =IF(Date!G34="","",Date!G34) | H34: =IF(Date!H34="","",Date!H34) | I34: =IF(Date!I34="","",Date!I34)
D35: 대 수술 | F35: =IF(Date!F35="","",Date!F35) | G35: =IF(Date!G35="","",Date!G35) | H35: =IF(Date!H35="","",Date!H35) | I35: =IF(Date!I35="","",Date!I35)
D36: 대 수술 | F36: =IF(Date!F36="","",Date!F36) | G36: =IF(Date!G36="","",Date!G36) | H36: =IF(Date!H36="","",Date!H36) | I36: =IF(Date!I36="","",Date!I36)
A37: 입원 일당 | D37: 상해 입원 | F37: =IF(Date!F37="","",Date!F37) | G37: =IF(Date!G37="","",Date!G37) | H37: =IF(Date!H37="","",Date!H37) | I37: =IF(Date!I37="","",Date!I37)
D38: 질병 입원 | F38: =IF(Date!F38="","",Date!F38) | G38: =IF(Date!G38="","",Date!G38) | H38: =IF(Date!H38="","",Date!H38) | I38: =IF(Date!I38="","",Date!I38)
D39: 1인실 | F39: =IF(Date!F39="","",Date!F39) | G39: =IF(Date!G39="","",Date!G39) | H39: =IF(Date!H39="","",Date!H39) | I39: =IF(Date!I39="","",Date!I39)
D40: 2~3인실 | F40: =IF(Date!F40="","",Date!F40) | G40: =IF(Date!G40="","",Date!G40) | H40: =IF(Date!H40="","",Date!H40) | I40: =IF(Date!I40="","",Date!I40)
...

Sheet 5칸
A1: =Date!Q1&"님 ("&Date!R1&"세, "&Date!S1&") 보험 보장 분석" -> 님 (세, ) 보험 보장 분석
K2: (만원)
A3: 납입기간 / 만기 | F3: =IF(Date!F3="","",Date!F3) | G3: =IF(Date!G3="","",Date!G3) | H3: =IF(Date!H3="","",Date!H3) | I3: =IF(Date!I3="","",Date!I3) | J3: =IF(Date!J3="","",Date!J3)
A4: 보험회사 | F4: =IF(Date!F4="","",Date!F4) | G4: =IF(Date!G4="","",Date!G4) | H4: =IF(Date!H4="","",Date!H4) | I4: =IF(Date!I4="","",Date!I4) | J4: =IF(Date!J4="","",Date!J4)
A5: 상품명 | F5: =IF(Date!F5="","",Date!F5) | G5: =IF(Date!G5="","",Date!G5) | H5: =IF(Date!H5="","",Date!H5) | I5: =IF(Date!I5="","",Date!I5) | J5: =IF(Date!J5="","",Date!J5)
A6: 가입년도 | F6: =IF(Date!F6="","",Date!F6) | G6: =IF(Date!G6="","",Date!G6) | H6: =IF(Date!H6="","",Date!H6) | I6: =IF(Date!I6="","",Date!I6) | J6: =IF(Date!J6="","",Date!J6)
A7: 납입보험료 | F7: =IF(Date!F7="","",Date!F7) | G7: =IF(Date!G7="","",Date!G7) | H7: =IF(Date!H7="","",Date!H7) | I7: =IF(Date!I7="","",Date!I7) | J7: =IF(Date!J7="","",Date!J7)
A8: 사망 | D8: 일반사망 | F8: =IF(Date!F8="","",Date!F8) | G8: =IF(Date!G8="","",Date!G8) | H8: =IF(Date!H8="","",Date!H8) | I8: =IF(Date!I8="","",Date!I8) | J8: =IF(Date!J8="","",Date!J8)
D9: 상해사망 | F9: =IF(Date!F9="","",Date!F9) | G9: =IF(Date!G9="","",Date!G9) | H9: =IF(Date!H9="","",Date!H9) | I9: =IF(Date!I9="","",Date!I9) | J9: =IF(Date!J9="","",Date!J9)
D10: 질병사망 | F10: =IF(Date!F10="","",Date!F10) | G10: =IF(Date!G10="","",Date!G10) | H10: =IF(Date!H10="","",Date!H10) | I10: =IF(Date!I10="","",Date!I10) | J10: =IF(Date!J10="","",Date!J10)
A11: 후유 장해 | D11: 상해 3%~ | F11: =IF(Date!F11="","",Date!F11) | G11: =IF(Date!G11="","",Date!G11) | H11: =IF(Date!H11="","",Date!H11) | I11: =IF(Date!I11="","",Date!I11) | J11: =IF(Date!J11="","",Date!J11)
D12: 질병 3%~ | F12: =IF(Date!F12="","",Date!F12) | G12: =IF(Date!G12="","",Date!G12) | H12: =IF(Date!H12="","",Date!H12) | I12: =IF(Date!I12="","",Date!I12) | J12: =IF(Date!J12="","",Date!J12)
A13: 3대 진단 · 수술 | C13: 암 | D13: 고액암 | F13: =IF(Date!F13="","",Date!F13) | G13: =IF(Date!G13="","",Date!G13) | H13: =IF(Date!H13="","",Date!H13) | I13: =IF(Date!I13="","",Date!I13) | J13: =IF(Date!J13="","",Date!J13)
D14: 일반암 | F14: =IF(Date!F14="","",Date!F14) | G14: =IF(Date!G14="","",Date!G14) | H14: =IF(Date!H14="","",Date!H14) | I14: =IF(Date!I14="","",Date!I14) | J14: =IF(Date!J14="","",Date!J14)
D15: 유사암(갑,기,경,제) | F15: =IF(Date!F15="","",Date!F15) | G15: =IF(Date!G15="","",Date!G15) | H15: =IF(Date!H15="","",Date!H15) | I15: =IF(Date!I15="","",Date!I15) | J15: =IF(Date!J15="","",Date!J15)
D16: 재진단암 / 전이암 | F16: =IF(Date!F16="","",Date!F16) | G16: =IF(Date!G16="","",Date!G16) | H16: =IF(Date!H16="","",Date!H16) | I16: =IF(Date!I16="","",Date!I16) | J16: =IF(Date!J16="","",Date!J16)
D17: 항암 방사선 / 약물 | F17: =IF(Date!F17="","",Date!F17) | G17: =IF(Date!G17="","",Date!G17) | H17: =IF(Date!H17="","",Date!H17) | I17: =IF(Date!I17="","",Date!I17) | J17: =IF(Date!J17="","",Date!J17)
D18: 암수술비 | F18: =IF(Date!F18="","",Date!F18) | G18: =IF(Date!G18="","",Date!G18) | H18: =IF(Date!H18="","",Date!H18) | I18: =IF(Date!I18="","",Date!I18) | J18: =IF(Date!J18="","",Date!J18)
D19: 암중환자 | F19: =IF(Date!F19="","",Date!F19) | G19: =IF(Date!G19="","",Date!G19) | H19: =IF(Date!H19="","",Date!H19) | I19: =IF(Date!I19="","",Date!I19) | J19: =IF(Date!J19="","",Date!J19)
D20: 표적항암 / 카티 | F20: =IF(Date!F20="","",Date!F20) | G20: =IF(Date!G20="","",Date!G20) | H20: =IF(Date!H20="","",Date!H20) | I20: =IF(Date!I20="","",Date!I20) | J20: =IF(Date!J20="","",Date!J20)
D21: 암특정치료비 | F21: =IF(Date!F21="","",Date!F21) | G21: =IF(Date!G21="","",Date!G21) | H21: =IF(Date!H21="","",Date!H21) | I21: =IF(Date!I21="","",Date!I21) | J21: =IF(Date!J21="","",Date!J21)
C22: 뇌 | D22: 뇌경색 / 뇌출혈 진단 | F22: =IF(Date!F22="","",Date!F22) | G22: =IF(Date!G22="","",Date!G22) | H22: =IF(Date!H22="","",Date!H22) | I22: =IF(Date!I22="","",Date!I22) | J22: =IF(Date!J22="","",Date!J22)
D23: 뇌졸중 진단 | F23: =IF(Date!F23="","",Date!F23) | G23: =IF(Date!G23="","",Date!G23) | H23: =IF(Date!H23="","",Date!H23) | I23: =IF(Date!I23="","",Date!I23) | J23: =IF(Date!J23="","",Date!J23)
D24: 뇌혈관 진단 | F24: =IF(Date!F24="","",Date!F24) | G24: =IF(Date!G24="","",Date!G24) | H24: =IF(Date!H24="","",Date!H24) | I24: =IF(Date!I24="","",Date!I24) | J24: =IF(Date!J24="","",Date!J24)
D25: 뇌혈관 수술 | F25: =IF(Date!F25="","",Date!F25) | G25: =IF(Date!G25="","",Date!G25) | H25: =IF(Date!H25="","",Date!H25) | I25: =IF(Date!I25="","",Date!I25) | J25: =IF(Date!J25="","",Date!J25)
C26: 심장 | D26: 급성심근경색 진단 | F26: =IF(Date!F26="","",Date!F26) | G26: =IF(Date!G26="","",Date!G26) | H26: =IF(Date!H26="","",Date!H26) | I26: =IF(Date!I26="","",Date!I26) | J26: =IF(Date!J26="","",Date!J26)
D27: 심혈관 진단 | F27: =IF(Date!F27="","",Date!F27) | G27: =IF(Date!G27="","",Date!G27) | H27: =IF(Date!H27="","",Date!H27) | I27: =IF(Date!I27="","",Date!I27) | J27: =IF(Date!J27="","",Date!J27)
D28: 심혈관 수술 | F28: =IF(Date!F28="","",Date!F28) | G28: =IF(Date!G28="","",Date!G28) | H28: =IF(Date!H28="","",Date!H28) | I28: =IF(Date!I28="","",Date!I28) | J28: =IF(Date!J28="","",Date!J28)
A29: 산정특례 | D29: 1회 | F29: =IF(Date!F29="","",Date!F29) | G29: =IF(Date!G29="","",Date!G29) | H29: =IF(Date!H29="","",Date!H29) | I29: =IF(Date!I29="","",Date!I29) | J29: =IF(Date!J29="","",Date!J29)
D30: 년 1회 | F30: =IF(Date!F30="","",Date!F30) | G30: =IF(Date!G30="","",Date!G30) | H30: =IF(Date!H30="","",Date!H30) | I30: =IF(Date!I30="","",Date!I30) | J30: =IF(Date!J30="","",Date!J30)
A31: 수술 | C31: 상해 | D31: 상해 수술 | F31: =IF(Date!F31="","",Date!F31) | G31: =IF(Date!G31="","",Date!G31) | H31: =IF(Date!H31="","",Date!H31) | I31: =IF(Date!I31="","",Date!I31) | J31: =IF(Date!J31="","",Date!J31)
D32: 상해(1~5)종 수술 | F32: =IF(Date!F32="","",Date!F32) | G32: =IF(Date!G32="","",Date!G32) | H32: =IF(Date!H32="","",Date!H32) | I32: =IF(Date!I32="","",Date!I32) | J32: =IF(Date!J32="","",Date!J32)
C33: 질병 | D33: 질병 수술 | F33: =IF(Date!F33="","",Date!F33) | G33: =IF(Date!G33="","",Date!G33) | H33: =IF(Date!H33="","",Date!H33) | I33: =IF(Date!I33="","",Date!I33) | J33: =IF(Date!J33="","",Date!J33)
D34: 질병(1~5)종 수술 | F34: =IF(Date!F34="","",Date!F34) | G34: =IF(Date!G34="","",Date!G34) | H34: =IF(Date!H34="","",Date!H34) | I34: =IF(Date!I34="","",Date!I34) | J34: =IF(Date!J34="","",Date!J34)
D35: 대 수술 | F35: =IF(Date!F35="","",Date!F35) | G35: =IF(Date!G35="","",Date!G35) | H35: =IF(Date!H35="","",Date!H35) | I35: =IF(Date!I35="","",Date!I35) | J35: =IF(Date!J35="","",Date!J35)
D36: 대 수술 | F36: =IF(Date!F36="","",Date!F36) | G36: =IF(Date!G36="","",Date!G36) | H36: =IF(Date!H36="","",Date!H36) | I36: =IF(Date!I36="","",Date!I36) | J36: =IF(Date!J36="","",Date!J36)
A37: 입원 일당 | D37: 상해 입원 | F37: =IF(Date!F37="","",Date!F37) | G37: =IF(Date!G37="","",Date!G37) | H37: =IF(Date!H37="","",Date!H37) | I37: =IF(Date!I37="","",Date!I37) | J37: =IF(Date!J37="","",Date!J37)
D38: 질병 입원 | F38: =IF(Date!F38="","",Date!F38) | G38: =IF(Date!G38="","",Date!G38) | H38: =IF(Date!H38="","",Date!H38) | I38: =IF(Date!I38="","",Date!I38) | J38: =IF(Date!J38="","",Date!J38)
D39: 1인실 | F39: =IF(Date!F39="","",Date!F39) | G39: =IF(Date!G39="","",Date!G39) | H39: =IF(Date!H39="","",Date!H39) | I39: =IF(Date!I39="","",Date!I39) | J39: =IF(Date!J39="","",Date!J39)
D40: 2~3인실 | F40: =IF(Date!F40="","",Date!F40) | G40: =IF(Date!G40="","",Date!G40) | H40: =IF(Date!H40="","",Date!H40) | I40: =IF(Date!I40="","",Date!I40) | J40: =IF(Date!J40="","",Date!J40)
...

Sheet 6칸
A1: =Date!Q1&"님 ("&Date!R1&"세, "&Date!S1&") 보험 보장 분석" -> 님 (세, ) 보험 보장 분석
L2: (만원)
A3: 납입기간 / 만기 | F3: =IF(Date!F3="","",Date!F3) | G3: =IF(Date!G3="","",Date!G3) | H3: =IF(Date!H3="","",Date!H3) | I3: =IF(Date!I3="","",Date!I3) | J3: =IF(Date!J3="","",Date!J3) | K3: =IF(Date!K3="","",Date!K3)
A4: 보험회사 | F4: =IF(Date!F4="","",Date!F4) | G4: =IF(Date!G4="","",Date!G4) | H4: =IF(Date!H4="","",Date!H4) | I4: =IF(Date!I4="","",Date!I4) | J4: =IF(Date!J4="","",Date!J4) | K4: =IF(Date!K4="","",Date!K4)
A5: 상품명 | F5: =IF(Date!F5="","",Date!F5) | G5: =IF(Date!G5="","",Date!G5) | H5: =IF(Date!H5="","",Date!H5) | I5: =IF(Date!I5="","",Date!I5) | J5: =IF(Date!J5="","",Date!J5) | K5: =IF(Date!K5="","",Date!K5)
A6: 가입년도 | F6: =IF(Date!F6="","",Date!F6) | G6: =IF(Date!G6="","",Date!G6) | H6: =IF(Date!H6="","",Date!H6) | I6: =IF(Date!I6="","",Date!I6) | J6: =IF(Date!J6="","",Date!J6) | K6: =IF(Date!K6="","",Date!K6)
A7: 납입보험료 | F7: =IF(Date!F7="","",Date!F7) | G7: =IF(Date!G7="","",Date!G7) | H7: =IF(Date!H7="","",Date!H7) | I7: =IF(Date!I7="","",Date!I7) | J7: =IF(Date!J7="","",Date!J7) | K7: =IF(Date!K7="","",Date!K7)
A8: 사망 | D8: 일반사망 | F8: =IF(Date!F8="","",Date!F8) | G8: =IF(Date!G8="","",Date!G8) | H8: =IF(Date!H8="","",Date!H8) | I8: =IF(Date!I8="","",Date!I8) | J8: =IF(Date!J8="","",Date!J8) | K8: =IF(Date!K8="","",Date!K8)
D9: 상해사망 | F9: =IF(Date!F9="","",Date!F9) | G9: =IF(Date!G9="","",Date!G9) | H9: =IF(Date!H9="","",Date!H9) | I9: =IF(Date!I9="","",Date!I9) | J9: =IF(Date!J9="","",Date!J9) | K9: =IF(Date!K9="","",Date!K9)
D10: 질병사망 | F10: =IF(Date!F10="","",Date!F10) | G10: =IF(Date!G10="","",Date!G10) | H10: =IF(Date!H10="","",Date!H10) | I10: =IF(Date!I10="","",Date!I10) | J10: =IF(Date!J10="","",Date!J10) | K10: =IF(Date!K10="","",Date!K10)
A11: 후유 장해 | D11: 상해 3%~ | F11: =IF(Date!F11="","",Date!F11) | G11: =IF(Date!G11="","",Date!G11) | H11: =IF(Date!H11="","",Date!H11) | I11: =IF(Date!I11="","",Date!I11) | J11: =IF(Date!J11="","",Date!J11) | K11: =IF(Date!K11="","",Date!K11)
D12: 질병 3%~ | F12: =IF(Date!F12="","",Date!F12) | G12: =IF(Date!G12="","",Date!G12) | H12: =IF(Date!H12="","",Date!H12) | I12: =IF(Date!I12="","",Date!I12) | J12: =IF(Date!J12="","",Date!J12) | K12: =IF(Date!K12="","",Date!K12)
A13: 3대 진단 · 수술 | C13: 암 | D13: 고액암 | F13: =IF(Date!F13="","",Date!F13) | G13: =IF(Date!G13="","",Date!G13) | H13: =IF(Date!H13="","",Date!H13) | I13: =IF(Date!I13="","",Date!I13) | J13: =IF(Date!J13="","",Date!J13) | K13: =IF(Date!K13="","",Date!K13)
D14: 일반암 | F14: =IF(Date!F14="","",Date!F14) | G14: =IF(Date!G14="","",Date!G14) | H14: =IF(Date!H14="","",Date!H14) | I14: =IF(Date!I14="","",Date!I14) | J14: =IF(Date!J14="","",Date!J14) | K14: =IF(Date!K14="","",Date!K14)
D15: 유사암(갑,기,경,제) | F15: =IF(Date!F15="","",Date!F15) | G15: =IF(Date!G15="","",Date!G15) | H15: =IF(Date!H15="","",Date!H15) | I15: =IF(Date!I15="","",Date!I15) | J15: =IF(Date!J15="","",Date!J15) | K15: =IF(Date!K15="","",Date!K15)
D16: 재진단암 / 전이암 | F16: =IF(Date!F16="","",Date!F16) | G16: =IF(Date!G16="","",Date!G16) | H16: =IF(Date!H16="","",Date!H16) | I16: =IF(Date!I16="","",Date!I16) | J16: =IF(Date!J16="","",Date!J16) | K16: =IF(Date!K16="","",Date!K16)
D17: 항암 방사선 / 약물 | F17: =IF(Date!F17="","",Date!F17) | G17: =IF(Date!G17="","",Date!G17) | H17: =IF(Date!H17="","",Date!H17) | I17: =IF(Date!I17="","",Date!I17) | J17: =IF(Date!J17="","",Date!J17) | K17: =IF(Date!K17="","",Date!K17)
D18: 암수술비 | F18: =IF(Date!F18="","",Date!F18) | G18: =IF(Date!G18="","",Date!G18) | H18: =IF(Date!H18="","",Date!H18) | I18: =IF(Date!I18="","",Date!I18) | J18: =IF(Date!J18="","",Date!J18) | K18: =IF(Date!K18="","",Date!K18)
D19: 암중환자 | F19: =IF(Date!F19="","",Date!F19) | G19: =IF(Date!G19="","",Date!G19) | H19: =IF(Date!H19="","",Date!H19) | I19: =IF(Date!I19="","",Date!I19) | J19: =IF(Date!J19="","",Date!J19) | K19: =IF(Date!K19="","",Date!K19)
D20: 표적항암 / 카티 | F20: =IF(Date!F20="","",Date!F20) | G20: =IF(Date!G20="","",Date!G20) | H20: =IF(Date!H20="","",Date!H20) | I20: =IF(Date!I20="","",Date!I20) | J20: =IF(Date!J20="","",Date!J20) | K20: =IF(Date!K20="","",Date!K20)
D21: 암특정치료비 | F21: =IF(Date!F21="","",Date!F21) | G21: =IF(Date!G21="","",Date!G21) | H21: =IF(Date!H21="","",Date!H21) | I21: =IF(Date!I21="","",Date!I21) | J21: =IF(Date!J21="","",Date!J21) | K21: =IF(Date!K21="","",Date!K21)
C22: 뇌 | D22: 뇌경색 / 뇌출혈 진단 | F22: =IF(Date!F22="","",Date!F22) | G22: =IF(Date!G22="","",Date!G22) | H22: =IF(Date!H22="","",Date!H22) | I22: =IF(Date!I22="","",Date!I22) | J22: =IF(Date!J22="","",Date!J22) | K22: =IF(Date!K22="","",Date!K22)
D23: 뇌졸중 진단 | F23: =IF(Date!F23="","",Date!F23) | G23: =IF(Date!G23="","",Date!G23) | H23: =IF(Date!H23="","",Date!H23) | I23: =IF(Date!I23="","",Date!I23) | J23: =IF(Date!J23="","",Date!J23) | K23: =IF(Date!K23="","",Date!K23)
D24: 뇌혈관 진단 | F24: =IF(Date!F24="","",Date!F24) | G24: =IF(Date!G24="","",Date!G24) | H24: =IF(Date!H24="","",Date!H24) | I24: =IF(Date!I24="","",Date!I24) | J24: =IF(Date!J24="","",Date!J24) | K24: =IF(Date!K24="","",Date!K24)
D25: 뇌혈관 수술 | F25: =IF(Date!F25="","",Date!F25) | G25: =IF(Date!G25="","",Date!G25) | H25: =IF(Date!H25="","",Date!H25) | I25: =IF(Date!I25="","",Date!I25) | J25: =IF(Date!J25="","",Date!J25) | K25: =IF(Date!K25="","",Date!K25)
C26: 심장 | D26: 급성심근경색 진단 | F26: =IF(Date!F26="","",Date!F26) | G26: =IF(Date!G26="","",Date!G26) | H26: =IF(Date!H26="","",Date!H26) | I26: =IF(Date!I26="","",Date!I26) | J26: =IF(Date!J26="","",Date!J26) | K26: =IF(Date!K26="","",Date!K26)
D27: 심혈관 진단 | F27: =IF(Date!F27="","",Date!F27) | G27: =IF(Date!G27="","",Date!G27) | H27: =IF(Date!H27="","",Date!H27) | I27: =IF(Date!I27="","",Date!I27) | J27: =IF(Date!J27="","",Date!J27) | K27: =IF(Date!K27="","",Date!K27)
D28: 심혈관 수술 | F28: =IF(Date!F28="","",Date!F28) | G28: =IF(Date!G28="","",Date!G28) | H28: =IF(Date!H28="","",Date!H28) | I28: =IF(Date!I28="","",Date!I28) | J28: =IF(Date!J28="","",Date!J28) | K28: =IF(Date!K28="","",Date!K28)
A29: 산정특례 | D29: 1회 | F29: =IF(Date!F29="","",Date!F29) | G29: =IF(Date!G29="","",Date!G29) | H29: =IF(Date!H29="","",Date!H29) | I29: =IF(Date!I29="","",Date!I29) | J29: =IF(Date!J29="","",Date!J29) | K29: =IF(Date!K29="","",Date!K29)
D30: 년 1회 | F30: =IF(Date!F30="","",Date!F30) | G30: =IF(Date!G30="","",Date!G30) | H30: =IF(Date!H30="","",Date!H30) | I30: =IF(Date!I30="","",Date!I30) | J30: =IF(Date!J30="","",Date!J30) | K30: =IF(Date!K30="","",Date!K30)
A31: 수술 | C31: 상해 | D31: 상해 수술 | F31: =IF(Date!F31="","",Date!F31) | G31: =IF(Date!G31="","",Date!G31) | H31: =IF(Date!H31="","",Date!H31) | I31: =IF(Date!I31="","",Date!I31) | J31: =IF(Date!J31="","",Date!J31) | K31: =IF(Date!K31="","",Date!K31)
D32: 상해(1~5)종 수술 | F32: =IF(Date!F32="","",Date!F32) | G32: =IF(Date!G32="","",Date!G32) | H32: =IF(Date!H32="","",Date!H32) | I32: =IF(Date!I32="","",Date!I32) | J32: =IF(Date!J32="","",Date!J32) | K32: =IF(Date!K32="","",Date!K32)
C33: 질병 | D33: 질병 수술 | F33: =IF(Date!F33="","",Date!F33) | G33: =IF(Date!G33="","",Date!G33) | H33: =IF(Date!H33="","",Date!H33) | I33: =IF(Date!I33="","",Date!I33) | J33: =IF(Date!J33="","",Date!J33) | K33: =IF(Date!K33="","",Date!K33)
D34: 질병(1~5)종 수술 | F34: =IF(Date!F34="","",Date!F34) | G34: =IF(Date!G34="","",Date!G34) | H34: =IF(Date!H34="","",Date!H34) | I34: =IF(Date!I34="","",Date!I34) | J34: =IF(Date!J34="","",Date!J34) | K34: =IF(Date!K34="","",Date!K34)
D35: 대 수술 | F35: =IF(Date!F35="","",Date!F35) | G35: =IF(Date!G35="","",Date!G35) | H35: =IF(Date!H35="","",Date!H35) | I35: =IF(Date!I35="","",Date!I35) | J35: =IF(Date!J35="","",Date!J35) | K35: =IF(Date!K35="","",Date!K35)
D36: 대 수술 | F36: =IF(Date!F36="","",Date!F36) | G36: =IF(Date!G36="","",Date!G36) | H36: =IF(Date!H36="","",Date!H36) | I36: =IF(Date!I36="","",Date!I36) | J36: =IF(Date!J36="","",Date!J36) | K36: =IF(Date!K36="","",Date!K36)
A37: 입원 일당 | D37: 상해 입원 | F37: =IF(Date!F37="","",Date!F37) | G37: =IF(Date!G37="","",Date!G37) | H37: =IF(Date!H37="","",Date!H37) | I37: =IF(Date!I37="","",Date!I37) | J37: =IF(Date!J37="","",Date!J37) | K37: =IF(Date!K37="","",Date!K37)
D38: 질병 입원 | F38: =IF(Date!F38="","",Date!F38) | G38: =IF(Date!G38="","",Date!G38) | H38: =IF(Date!H38="","",Date!H38) | I38: =IF(Date!I38="","",Date!I38) | J38: =IF(Date!J38="","",Date!J38) | K38: =IF(Date!K38="","",Date!K38)
D39: 1인실 | F39: =IF(Date!F39="","",Date!F39) | G39: =IF(Date!G39="","",Date!G39) | H39: =IF(Date!H39="","",Date!H39) | I39: =IF(Date!I39="","",Date!I39) | J39: =IF(Date!J39="","",Date!J39) | K39: =IF(Date!K39="","",Date!K39)
D40: 2~3인실 | F40: =IF(Date!F40="","",Date!F40) | G40: =IF(Date!G40="","",Date!G40) | H40: =IF(Date!H40="","",Date!H40) | I40: =IF(Date!I40="","",Date!I40) | J40: =IF(Date!J40="","",Date!J40) | K40: =IF(Date!K40="","",Date!K40)
...

Sheet 7칸
A1: =Date!Q1&"님 ("&Date!R1&"세, "&Date!S1&") 보험 보장 분석" -> 님 (세, ) 보험 보장 분석
M2: (만원)
A3: 납입기간 / 만기 | F3: =IF(Date!F3="","",Date!F3) | G3: =IF(Date!G3="","",Date!G3) | H3: =IF(Date!H3="","",Date!H3) | I3: =IF(Date!I3="","",Date!I3) | J3: =IF(Date!J3="","",Date!J3) | K3: =IF(Date!K3="","",Date!K3) | L3: =IF(Date!L3="","",Date!L3)
A4: 보험회사 | F4: =IF(Date!F4="","",Date!F4) | G4: =IF(Date!G4="","",Date!G4) | H4: =IF(Date!H4="","",Date!H4) | I4: =IF(Date!I4="","",Date!I4) | J4: =IF(Date!J4="","",Date!J4) | K4: =IF(Date!K4="","",Date!K4) | L4: =IF(Date!L4="","",Date!L4)
A5: 상품명 | F5: =IF(Date!F5="","",Date!F5) | G5: =IF(Date!G5="","",Date!G5) | H5: =IF(Date!H5="","",Date!H5) | I5: =IF(Date!I5="","",Date!I5) | J5: =IF(Date!J5="","",Date!J5) | K5: =IF(Date!K5="","",Date!K5) | L5: =IF(Date!L5="","",Date!L5)
A6: 가입년도 | F6: =IF(Date!F6="","",Date!F6) | G6: =IF(Date!G6="","",Date!G6) | H6: =IF(Date!H6="","",Date!H6) | I6: =IF(Date!I6="","",Date!I6) | J6: =IF(Date!J6="","",Date!J6) | K6: =IF(Date!K6="","",Date!K6) | L6: =IF(Date!L6="","",Date!L6)
A7: 납입보험료 | F7: =IF(Date!F7="","",Date!F7) | G7: =IF(Date!G7="","",Date!G7) | H7: =IF(Date!H7="","",Date!H7) | I7: =IF(Date!I7="","",Date!I7) | J7: =IF(Date!J7="","",Date!J7) | K7: =IF(Date!K7="","",Date!K7) | L7: =IF(Date!L7="","",Date!L7)
A8: 사망 | D8: 일반사망 | F8: =IF(Date!F8="","",Date!F8) | G8: =IF(Date!G8="","",Date!G8) | H8: =IF(Date!H8="","",Date!H8) | I8: =IF(Date!I8="","",Date!I8) | J8: =IF(Date!J8="","",Date!J8) | K8: =IF(Date!K8="","",Date!K8) | L8: =IF(Date!L8="","",Date!L8)
D9: 상해사망 | F9: =IF(Date!F9="","",Date!F9) | G9: =IF(Date!G9="","",Date!G9) | H9: =IF(Date!H9="","",Date!H9) | I9: =IF(Date!I9="","",Date!I9) | J9: =IF(Date!J9="","",Date!J9) | K9: =IF(Date!K9="","",Date!K9) | L9: =IF(Date!L9="","",Date!L9)
D10: 질병사망 | F10: =IF(Date!F10="","",Date!F10) | G10: =IF(Date!G10="","",Date!G10) | H10: =IF(Date!H10="","",Date!H10) | I10: =IF(Date!I10="","",Date!I10) | J10: =IF(Date!J10="","",Date!J10) | K10: =IF(Date!K10="","",Date!K10) | L10: =IF(Date!L10="","",Date!L10)
A11: 후유 장해 | D11: 상해 3%~ | F11: =IF(Date!F11="","",Date!F11) | G11: =IF(Date!G11="","",Date!G11) | H11: =IF(Date!H11="","",Date!H11) | I11: =IF(Date!I11="","",Date!I11) | J11: =IF(Date!J11="","",Date!J11) | K11: =IF(Date!K11="","",Date!K11) | L11: =IF(Date!L11="","",Date!L11)
D12: 질병 3%~ | F12: =IF(Date!F12="","",Date!F12) | G12: =IF(Date!G12="","",Date!G12) | H12: =IF(Date!H12="","",Date!H12) | I12: =IF(Date!I12="","",Date!I12) | J12: =IF(Date!J12="","",Date!J12) | K12: =IF(Date!K12="","",Date!K12) | L12: =IF(Date!L12="","",Date!L12)
A13: 3대 진단 · 수술 | C13: 암 | D13: 고액암 | F13: =IF(Date!F13="","",Date!F13) | G13: =IF(Date!G13="","",Date!G13) | H13: =IF(Date!H13="","",Date!H13) | I13: =IF(Date!I13="","",Date!I13) | J13: =IF(Date!J13="","",Date!J13) | K13: =IF(Date!K13="","",Date!K13) | L13: =IF(Date!L13="","",Date!L13)
D14: 일반암 | F14: =IF(Date!F14="","",Date!F14) | G14: =IF(Date!G14="","",Date!G14) | H14: =IF(Date!H14="","",Date!H14) | I14: =IF(Date!I14="","",Date!I14) | J14: =IF(Date!J14="","",Date!J14) | K14: =IF(Date!K14="","",Date!K14) | L14: =IF(Date!L14="","",Date!L14)
D15: 유사암(갑,기,경,제) | F15: =IF(Date!F15="","",Date!F15) | G15: =IF(Date!G15="","",Date!G15) | H15: =IF(Date!H15="","",Date!H15) | I15: =IF(Date!I15="","",Date!I15) | J15: =IF(Date!J15="","",Date!J15) | K15: =IF(Date!K15="","",Date!K15) | L15: =IF(Date!L15="","",Date!L15)
D16: 재진단암 / 전이암 | F16: =IF(Date!F16="","",Date!F16) | G16: =IF(Date!G16="","",Date!G16) | H16: =IF(Date!H16="","",Date!H16) | I16: =IF(Date!I16="","",Date!I16) | J16: =IF(Date!J16="","",Date!J16) | K16: =IF(Date!K16="","",Date!K16) | L16: =IF(Date!L16="","",Date!L16)
D17: 항암 방사선 / 약물 | F17: =IF(Date!F17="","",Date!F17) | G17: =IF(Date!G17="","",Date!G17) | H17: =IF(Date!H17="","",Date!H17) | I17: =IF(Date!I17="","",Date!I17) | J17: =IF(Date!J17="","",Date!J17) | K17: =IF(Date!K17="","",Date!K17) | L17: =IF(Date!L17="","",Date!L17)
D18: 암수술비 | F18: =IF(Date!F18="","",Date!F18) | G18: =IF(Date!G18="","",Date!G18) | H18: =IF(Date!H18="","",Date!H18) | I18: =IF(Date!I18="","",Date!I18) | J18: =IF(Date!J18="","",Date!J18) | K18: =IF(Date!K18="","",Date!K18) | L18: =IF(Date!L18="","",Date!L18)
D19: 암중환자 | F19: =IF(Date!F19="","",Date!F19) | G19: =IF(Date!G19="","",Date!G19) | H19: =IF(Date!H19="","",Date!H19) | I19: =IF(Date!I19="","",Date!I19) | J19: =IF(Date!J19="","",Date!J19) | K19: =IF(Date!K19="","",Date!K19) | L19: =IF(Date!L19="","",Date!L19)
D20: 표적항암 / 카티 | F20: =IF(Date!F20="","",Date!F20) | G20: =IF(Date!G20="","",Date!G20) | H20: =IF(Date!H20="","",Date!H20) | I20: =IF(Date!I20="","",Date!I20) | J20: =IF(Date!J20="","",Date!J20) | K20: =IF(Date!K20="","",Date!K20) | L20: =IF(Date!L20="","",Date!L20)
D21: 암특정치료비 | F21: =IF(Date!F21="","",Date!F21) | G21: =IF(Date!G21="","",Date!G21) | H21: =IF(Date!H21="","",Date!H21) | I21: =IF(Date!I21="","",Date!I21) | J21: =IF(Date!J21="","",Date!J21) | K21: =IF(Date!K21="","",Date!K21) | L21: =IF(Date!L21="","",Date!L21)
C22: 뇌 | D22: 뇌경색 / 뇌출혈 진단 | F22: =IF(Date!F22="","",Date!F22) | G22: =IF(Date!G22="","",Date!G22) | H22: =IF(Date!H22="","",Date!H22) | I22: =IF(Date!I22="","",Date!I22) | J22: =IF(Date!J22="","",Date!J22) | K22: =IF(Date!K22="","",Date!K22) | L22: =IF(Date!L22="","",Date!L22)
D23: 뇌졸중 진단 | F23: =IF(Date!F23="","",Date!F23) | G23: =IF(Date!G23="","",Date!G23) | H23: =IF(Date!H23="","",Date!H23) | I23: =IF(Date!I23="","",Date!I23) | J23: =IF(Date!J23="","",Date!J23) | K23: =IF(Date!K23="","",Date!K23) | L23: =IF(Date!L23="","",Date!L23)
D24: 뇌혈관 진단 | F24: =IF(Date!F24="","",Date!F24) | G24: =IF(Date!G24="","",Date!G24) | H24: =IF(Date!H24="","",Date!H24) | I24: =IF(Date!I24="","",Date!I24) | J24: =IF(Date!J24="","",Date!J24) | K24: =IF(Date!K24="","",Date!K24) | L24: =IF(Date!L24="","",Date!L24)
D25: 뇌혈관 수술 | F25: =IF(Date!F25="","",Date!F25) | G25: =IF(Date!G25="","",Date!G25) | H25: =IF(Date!H25="","",Date!H25) | I25: =IF(Date!I25="","",Date!I25) | J25: =IF(Date!J25="","",Date!J25) | K25: =IF(Date!K25="","",Date!K25) | L25: =IF(Date!L25="","",Date!L25)
C26: 심장 | D26: 급성심근경색 진단 | F26: =IF(Date!F26="","",Date!F26) | G26: =IF(Date!G26="","",Date!G26) | H26: =IF(Date!H26="","",Date!H26) | I26: =IF(Date!I26="","",Date!I26) | J26: =IF(Date!J26="","",Date!J26) | K26: =IF(Date!K26="","",Date!K26) | L26: =IF(Date!L26="","",Date!L26)
D27: 심혈관 진단 | F27: =IF(Date!F27="","",Date!F27) | G27: =IF(Date!G27="","",Date!G27) | H27: =IF(Date!H27="","",Date!H27) | I27: =IF(Date!I27="","",Date!I27) | J27: =IF(Date!J27="","",Date!J27) | K27: =IF(Date!K27="","",Date!K27) | L27: =IF(Date!L27="","",Date!L27)
D28: 심혈관 수술 | F28: =IF(Date!F28="","",Date!F28) | G28: =IF(Date!G28="","",Date!G28) | H28: =IF(Date!H28="","",Date!H28) | I28: =IF(Date!I28="","",Date!I28) | J28: =IF(Date!J28="","",Date!J28) | K28: =IF(Date!K28="","",Date!K28) | L28: =IF(Date!L28="","",Date!L28)
A29: 산정특례 | D29: 1회 | F29: =IF(Date!F29="","",Date!F29) | G29: =IF(Date!G29="","",Date!G29) | H29: =IF(Date!H29="","",Date!H29) | I29: =IF(Date!I29="","",Date!I29) | J29: =IF(Date!J29="","",Date!J29) | K29: =IF(Date!K29="","",Date!K29) | L29: =IF(Date!L29="","",Date!L29)
D30: 년 1회 | F30: =IF(Date!F30="","",Date!F30) | G30: =IF(Date!G30="","",Date!G30) | H30: =IF(Date!H30="","",Date!H30) | I30: =IF(Date!I30="","",Date!I30) | J30: =IF(Date!J30="","",Date!J30) | K30: =IF(Date!K30="","",Date!K30) | L30: =IF(Date!L30="","",Date!L30)
A31: 수술 | C31: 상해 | D31: 상해 수술 | F31: =IF(Date!F31="","",Date!F31) | G31: =IF(Date!G31="","",Date!G31) | H31: =IF(Date!H31="","",Date!H31) | I31: =IF(Date!I31="","",Date!I31) | J31: =IF(Date!J31="","",Date!J31) | K31: =IF(Date!K31="","",Date!K31) | L31: =IF(Date!L31="","",Date!L31)
D32: 상해(1~5)종 수술 | F32: =IF(Date!F32="","",Date!F32) | G32: =IF(Date!G32="","",Date!G32) | H32: =IF(Date!H32="","",Date!H32) | I32: =IF(Date!I32="","",Date!I32) | J32: =IF(Date!J32="","",Date!J32) | K32: =IF(Date!K32="","",Date!K32) | L32: =IF(Date!L32="","",Date!L32)
C33: 질병 | D33: 질병 수술 | F33: =IF(Date!F33="","",Date!F33) | G33: =IF(Date!G33="","",Date!G33) | H33: =IF(Date!H33="","",Date!H33) | I33: =IF(Date!I33="","",Date!I33) | J33: =IF(Date!J33="","",Date!J33) | K33: =IF(Date!K33="","",Date!K33) | L33: =IF(Date!L33="","",Date!L33)
D34: 질병(1~5)종 수술 | F34: =IF(Date!F34="","",Date!F34) | G34: =IF(Date!G34="","",Date!G34) | H34: =IF(Date!H34="","",Date!H34) | I34: =IF(Date!I34="","",Date!I34) | J34: =IF(Date!J34="","",Date!J34) | K34: =IF(Date!K34="","",Date!K34) | L34: =IF(Date!L34="","",Date!L34)
D35: 대 수술 | F35: =IF(Date!F35="","",Date!F35) | G35: =IF(Date!G35="","",Date!G35) | H35: =IF(Date!H35="","",Date!H35) | I35: =IF(Date!I35="","",Date!I35) | J35: =IF(Date!J35="","",Date!J35) | K35: =IF(Date!K35="","",Date!K35) | L35: =IF(Date!L35="","",Date!L35)
D36: 대 수술 | F36: =IF(Date!F36="","",Date!F36) | G36: =IF(Date!G36="","",Date!G36) | H36: =IF(Date!H36="","",Date!H36) | I36: =IF(Date!I36="","",Date!I36) | J36: =IF(Date!J36="","",Date!J36) | K36: =IF(Date!K36="","",Date!K36) | L36: =IF(Date!L36="","",Date!L36)
A37: 입원 일당 | D37: 상해 입원 | F37: =IF(Date!F37="","",Date!F37) | G37: =IF(Date!G37="","",Date!G37) | H37: =IF(Date!H37="","",Date!H37) | I37: =IF(Date!I37="","",Date!I37) | J37: =IF(Date!J37="","",Date!J37) | K37: =IF(Date!K37="","",Date!K37) | L37: =IF(Date!L37="","",Date!L37)
D38: 질병 입원 | F38: =IF(Date!F38="","",Date!F38) | G38: =IF(Date!G38="","",Date!G38) | H38: =IF(Date!H38="","",Date!H38) | I38: =IF(Date!I38="","",Date!I38) | J38: =IF(Date!J38="","",Date!J38) | K38: =IF(Date!K38="","",Date!K38) | L38: =IF(Date!L38="","",Date!L38)
D39: 1인실 | F39: =IF(Date!F39="","",Date!F39) | G39: =IF(Date!G39="","",Date!G39) | H39: =IF(Date!H39="","",Date!H39) | I39: =IF(Date!I39="","",Date!I39) | J39: =IF(Date!J39="","",Date!J39) | K39: =IF(Date!K39="","",Date!K39) | L39: =IF(Date!L39="","",Date!L39)
D40: 2~3인실 | F40: =IF(Date!F40="","",Date!F40) | G40: =IF(Date!G40="","",Date!G40) | H40: =IF(Date!H40="","",Date!H40) | I40: =IF(Date!I40="","",Date!I40) | J40: =IF(Date!J40="","",Date!J40) | K40: =IF(Date!K40="","",Date!K40) | L40: =IF(Date!L40="","",Date!L40)
...

Sheet 8칸
A1: =Date!Q1&"님 ("&Date!R1&"세, "&Date!S1&") 보험 보장 분석" -> 님 (세, ) 보험 보장 분석
N2: (만원)
A3: 납입기간 / 만기 | F3: =IF(Date!F3="","",Date!F3) | G3: =IF(Date!G3="","",Date!G3) | H3: =IF(Date!H3="","",Date!H3) | I3: =IF(Date!I3="","",Date!I3) | J3: =IF(Date!J3="","",Date!J3) | K3: =IF(Date!K3="","",Date!K3) | L3: =IF(Date!L3="","",Date!L3) | M3: =IF(Date!M3="","",Date!M3)
A4: 보험회사 | F4: =IF(Date!F4="","",Date!F4) | G4: =IF(Date!G4="","",Date!G4) | H4: =IF(Date!H4="","",Date!H4) | I4: =IF(Date!I4="","",Date!I4) | J4: =IF(Date!J4="","",Date!J4) | K4: =IF(Date!K4="","",Date!K4) | L4: =IF(Date!L4="","",Date!L4) | M4: =IF(Date!M4="","",Date!M4)
A5: 상품명 | F5: =IF(Date!F5="","",Date!F5) | G5: =IF(Date!G5="","",Date!G5) | H5: =IF(Date!H5="","",Date!H5) | I5: =IF(Date!I5="","",Date!I5) | J5: =IF(Date!J5="","",Date!J5) | K5: =IF(Date!K5="","",Date!K5) | L5: =IF(Date!L5="","",Date!L5) | M5: =IF(Date!M5="","",Date!M5)
A6: 가입년도 | F6: =IF(Date!F6="","",Date!F6) | G6: =IF(Date!G6="","",Date!G6) | H6: =IF(Date!H6="","",Date!H6) | I6: =IF(Date!I6="","",Date!I6) | J6: =IF(Date!J6="","",Date!J6) | K6: =IF(Date!K6="","",Date!K6) | L6: =IF(Date!L6="","",Date!L6) | M6: =IF(Date!M6="","",Date!M6)
A7: 납입보험료 | F7: =IF(Date!F7="","",Date!F7) | G7: =IF(Date!G7="","",Date!G7) | H7: =IF(Date!H7="","",Date!H7) | I7: =IF(Date!I7="","",Date!I7) | J7: =IF(Date!J7="","",Date!J7) | K7: =IF(Date!K7="","",Date!K7) | L7: =IF(Date!L7="","",Date!L7) | M7: =IF(Date!M7="","",Date!M7)
A8: 사망 | D8: 일반사망 | F8: =IF(Date!F8="","",Date!F8) | G8: =IF(Date!G8="","",Date!G8) | H8: =IF(Date!H8="","",Date!H8) | I8: =IF(Date!I8="","",Date!I8) | J8: =IF(Date!J8="","",Date!J8) | K8: =IF(Date!K8="","",Date!K8) | L8: =IF(Date!L8="","",Date!L8) | M8: =IF(Date!M8="","",Date!M8)
D9: 상해사망 | F9: =IF(Date!F9="","",Date!F9) | G9: =IF(Date!G9="","",Date!G9) | H9: =IF(Date!H9="","",Date!H9) | I9: =IF(Date!I9="","",Date!I9) | J9: =IF(Date!J9="","",Date!J9) | K9: =IF(Date!K9="","",Date!K9) | L9: =IF(Date!L9="","",Date!L9) | M9: =IF(Date!M9="","",Date!M9)
D10: 질병사망 | F10: =IF(Date!F10="","",Date!F10) | G10: =IF(Date!G10="","",Date!G10) | H10: =IF(Date!H10="","",Date!H10) | I10: =IF(Date!I10="","",Date!I10) | J10: =IF(Date!J10="","",Date!J10) | K10: =IF(Date!K10="","",Date!K10) | L10: =IF(Date!L10="","",Date!L10) | M10: =IF(Date!M10="","",Date!M10)
A11: 후유 장해 | D11: 상해 3%~ | F11: =IF(Date!F11="","",Date!F11) | G11: =IF(Date!G11="","",Date!G11) | H11: =IF(Date!H11="","",Date!H11) | I11: =IF(Date!I11="","",Date!I11) | J11: =IF(Date!J11="","",Date!J11) | K11: =IF(Date!K11="","",Date!K11) | L11: =IF(Date!L11="","",Date!L11) | M11: =IF(Date!M11="","",Date!M11)
D12: 질병 3%~ | F12: =IF(Date!F12="","",Date!F12) | G12: =IF(Date!G12="","",Date!G12) | H12: =IF(Date!H12="","",Date!H12) | I12: =IF(Date!I12="","",Date!I12) | J12: =IF(Date!J12="","",Date!J12) | K12: =IF(Date!K12="","",Date!K12) | L12: =IF(Date!L12="","",Date!L12) | M12: =IF(Date!M12="","",Date!M12)
A13: 3대 진단 · 수술 | C13: 암 | D13: 고액암 | F13: =IF(Date!F13="","",Date!F13) | G13: =IF(Date!G13="","",Date!G13) | H13: =IF(Date!H13="","",Date!H13) | I13: =IF(Date!I13="","",Date!I13) | J13: =IF(Date!J13="","",Date!J13) | K13: =IF(Date!K13="","",Date!K13) | L13: =IF(Date!L13="","",Date!L13) | M13: =IF(Date!M13="","",Date!M13)
D14: 일반암 | F14: =IF(Date!F14="","",Date!F14) | G14: =IF(Date!G14="","",Date!G14) | H14: =IF(Date!H14="","",Date!H14) | I14: =IF(Date!I14="","",Date!I14) | J14: =IF(Date!J14="","",Date!J14) | K14: =IF(Date!K14="","",Date!K14) | L14: =IF(Date!L14="","",Date!L14) | M14: =IF(Date!M14="","",Date!M14)
D15: 유사암(갑,기,경,제) | F15: =IF(Date!F15="","",Date!F15) | G15: =IF(Date!G15="","",Date!G15) | H15: =IF(Date!H15="","",Date!H15) | I15: =IF(Date!I15="","",Date!I15) | J15: =IF(Date!J15="","",Date!J15) | K15: =IF(Date!K15="","",Date!K15) | L15: =IF(Date!L15="","",Date!L15) | M15: =IF(Date!M15="","",Date!M15)
D16: 재진단암 / 전이암 | F16: =IF(Date!F16="","",Date!F16) | G16: =IF(Date!G16="","",Date!G16) | H16: =IF(Date!H16="","",Date!H16) | I16: =IF(Date!I16="","",Date!I16) | J16: =IF(Date!J16="","",Date!J16) | K16: =IF(Date!K16="","",Date!K16) | L16: =IF(Date!L16="","",Date!L16) | M16: =IF(Date!M16="","",Date!M16)
D17: 항암 방사선 / 약물 | F17: =IF(Date!F17="","",Date!F17) | G17: =IF(Date!G17="","",Date!G17) | H17: =IF(Date!H17="","",Date!H17) | I17: =IF(Date!I17="","",Date!I17) | J17: =IF(Date!J17="","",Date!J17) | K17: =IF(Date!K17="","",Date!K17) | L17: =IF(Date!L17="","",Date!L17) | M17: =IF(Date!M17="","",Date!M17)
D18: 암수술비 | F18: =IF(Date!F18="","",Date!F18) | G18: =IF(Date!G18="","",Date!G18) | H18: =IF(Date!H18="","",Date!H18) | I18: =IF(Date!I18="","",Date!I18) | J18: =IF(Date!J18="","",Date!J18) | K18: =IF(Date!K18="","",Date!K18) | L18: =IF(Date!L18="","",Date!L18) | M18: =IF(Date!M18="","",Date!M18)
D19: 암중환자 | F19: =IF(Date!F19="","",Date!F19) | G19: =IF(Date!G19="","",Date!G19) | H19: =IF(Date!H19="","",Date!H19) | I19: =IF(Date!I19="","",Date!I19) | J19: =IF(Date!J19="","",Date!J19) | K19: =IF(Date!K19="","",Date!K19) | L19: =IF(Date!L19="","",Date!L19) | M19: =IF(Date!M19="","",Date!M19)
D20: 표적항암 / 카티 | F20: =IF(Date!F20="","",Date!F20) | G20: =IF(Date!G20="","",Date!G20) | H20: =IF(Date!H20="","",Date!H20) | I20: =IF(Date!I20="","",Date!I20) | J20: =IF(Date!J20="","",Date!J20) | K20: =IF(Date!K20="","",Date!K20) | L20: =IF(Date!L20="","",Date!L20) | M20: =IF(Date!M20="","",Date!M20)
D21: 암특정치료비 | F21: =IF(Date!F21="","",Date!F21) | G21: =IF(Date!G21="","",Date!G21) | H21: =IF(Date!H21="","",Date!H21) | I21: =IF(Date!I21="","",Date!I21) | J21: =IF(Date!J21="","",Date!J21) | K21: =IF(Date!K21="","",Date!K21) | L21: =IF(Date!L21="","",Date!L21) | M21: =IF(Date!M21="","",Date!M21)
C22: 뇌 | D22: 뇌경색 / 뇌출혈 진단 | F22: =IF(Date!F22="","",Date!F22) | G22: =IF(Date!G22="","",Date!G22) | H22: =IF(Date!H22="","",Date!H22) | I22: =IF(Date!I22="","",Date!I22) | J22: =IF(Date!J22="","",Date!J22) | K22: =IF(Date!K22="","",Date!K22) | L22: =IF(Date!L22="","",Date!L22) | M22: =IF(Date!M22="","",Date!M22)
D23: 뇌졸중 진단 | F23: =IF(Date!F23="","",Date!F23) | G23: =IF(Date!G23="","",Date!G23) | H23: =IF(Date!H23="","",Date!H23) | I23: =IF(Date!I23="","",Date!I23) | J23: =IF(Date!J23="","",Date!J23) | K23: =IF(Date!K23="","",Date!K23) | L23: =IF(Date!L23="","",Date!L23) | M23: =IF(Date!M23="","",Date!M23)
D24: 뇌혈관 진단 | F24: =IF(Date!F24="","",Date!F24) | G24: =IF(Date!G24="","",Date!G24) | H24: =IF(Date!H24="","",Date!H24) | I24: =IF(Date!I24="","",Date!I24) | J24: =IF(Date!J24="","",Date!J24) | K24: =IF(Date!K24="","",Date!K24) | L24: =IF(Date!L24="","",Date!L24) | M24: =IF(Date!M24="","",Date!M24)
D25: 뇌혈관 수술 | F25: =IF(Date!F25="","",Date!F25) | G25: =IF(Date!G25="","",Date!G25) | H25: =IF(Date!H25="","",Date!H25) | I25: =IF(Date!I25="","",Date!I25) | J25: =IF(Date!J25="","",Date!J25) | K25: =IF(Date!K25="","",Date!K25) | L25: =IF(Date!L25="","",Date!L25) | M25: =IF(Date!M25="","",Date!M25)
C26: 심장 | D26: 급성심근경색 진단 | F26: =IF(Date!F26="","",Date!F26) | G26: =IF(Date!G26="","",Date!G26) | H26: =IF(Date!H26="","",Date!H26) | I26: =IF(Date!I26="","",Date!I26) | J26: =IF(Date!J26="","",Date!J26) | K26: =IF(Date!K26="","",Date!K26) | L26: =IF(Date!L26="","",Date!L26) | M26: =IF(Date!M26="","",Date!M26)
D27: 심혈관 진단 | F27: =IF(Date!F27="","",Date!F27) | G27: =IF(Date!G27="","",Date!G27) | H27: =IF(Date!H27="","",Date!H27) | I27: =IF(Date!I27="","",Date!I27) | J27: =IF(Date!J27="","",Date!J27) | K27: =IF(Date!K27="","",Date!K27) | L27: =IF(Date!L27="","",Date!L27) | M27: =IF(Date!M27="","",Date!M27)
D28: 심혈관 수술 | F28: =IF(Date!F28="","",Date!F28) | G28: =IF(Date!G28="","",Date!G28) | H28: =IF(Date!H28="","",Date!H28) | I28: =IF(Date!I28="","",Date!I28) | J28: =IF(Date!J28="","",Date!J28) | K28: =IF(Date!K28="","",Date!K28) | L28: =IF(Date!L28="","",Date!L28) | M28: =IF(Date!M28="","",Date!M28)
A29: 산정특례 | D29: 1회 | F29: =IF(Date!F29="","",Date!F29) | G29: =IF(Date!G29="","",Date!G29) | H29: =IF(Date!H29="","",Date!H29) | I29: =IF(Date!I29="","",Date!I29) | J29: =IF(Date!J29="","",Date!J29) | K29: =IF(Date!K29="","",Date!K29) | L29: =IF(Date!L29="","",Date!L29) | M29: =IF(Date!M29="","",Date!M29)
D30: 년 1회 | F30: =IF(Date!F30="","",Date!F30) | G30: =IF(Date!G30="","",Date!G30) | H30: =IF(Date!H30="","",Date!H30) | I30: =IF(Date!I30="","",Date!I30) | J30: =IF(Date!J30="","",Date!J30) | K30: =IF(Date!K30="","",Date!K30) | L30: =IF(Date!L30="","",Date!L30) | M30: =IF(Date!M30="","",Date!M30)
A31: 수술 | C31: 상해 | D31: 상해 수술 | F31: =IF(Date!F31="","",Date!F31) | G31: =IF(Date!G31="","",Date!G31) | H31: =IF(Date!H31="","",Date!H31) | I31: =IF(Date!I31="","",Date!I31) | J31: =IF(Date!J31="","",Date!J31) | K31: =IF(Date!K31="","",Date!K31) | L31: =IF(Date!L31="","",Date!L31) | M31: =IF(Date!M31="","",Date!M31)
D32: 상해(1~5)종 수술 | F32: =IF(Date!F32="","",Date!F32) | G32: =IF(Date!G32="","",Date!G32) | H32: =IF(Date!H32="","",Date!H32) | I32: =IF(Date!I32="","",Date!I32) | J32: =IF(Date!J32="","",Date!J32) | K32: =IF(Date!K32="","",Date!K32) | L32: =IF(Date!L32="","",Date!L32) | M32: =IF(Date!M32="","",Date!M32)
C33: 질병 | D33: 질병 수술 | F33: =IF(Date!F33="","",Date!F33) | G33: =IF(Date!G33="","",Date!G33) | H33: =IF(Date!H33="","",Date!H33) | I33: =IF(Date!I33="","",Date!I33) | J33: =IF(Date!J33="","",Date!J33) | K33: =IF(Date!K33="","",Date!K33) | L33: =IF(Date!L33="","",Date!L33) | M33: =IF(Date!M33="","",Date!M33)
D34: 질병(1~5)종 수술 | F34: =IF(Date!F34="","",Date!F34) | G34: =IF(Date!G34="","",Date!G34) | H34: =IF(Date!H34="","",Date!H34) | I34: =IF(Date!I34="","",Date!I34) | J34: =IF(Date!J34="","",Date!J34) | K34: =IF(Date!K34="","",Date!K34) | L34: =IF(Date!L34="","",Date!L34) | M34: =IF(Date!M34="","",Date!M34)
D35: 대 수술 | F35: =IF(Date!F35="","",Date!F35) | G35: =IF(Date!G35="","",Date!G35) | H35: =IF(Date!H35="","",Date!H35) | I35: =IF(Date!I35="","",Date!I35) | J35: =IF(Date!J35="","",Date!J35) | K35: =IF(Date!K35="","",Date!K35) | L35: =IF(Date!L35="","",Date!L35) | M35: =IF(Date!M35="","",Date!M35)
D36: 대 수술 | F36: =IF(Date!F36="","",Date!F36) | G36: =IF(Date!G36="","",Date!G36) | H36: =IF(Date!H36="","",Date!H36) | I36: =IF(Date!I36="","",Date!I36) | J36: =IF(Date!J36="","",Date!J36) | K36: =IF(Date!K36="","",Date!K36) | L36: =IF(Date!L36="","",Date!L36) | M36: =IF(Date!M36="","",Date!M36)
A37: 입원 일당 | D37: 상해 입원 | F37: =IF(Date!F37="","",Date!F37) | G37: =IF(Date!G37="","",Date!G37) | H37: =IF(Date!H37="","",Date!H37) | I37: =IF(Date!I37="","",Date!I37) | J37: =IF(Date!J37="","",Date!J37) | K37: =IF(Date!K37="","",Date!K37) | L37: =IF(Date!L37="","",Date!L37) | M37: =IF(Date!M37="","",Date!M37)
D38: 질병 입원 | F38: =IF(Date!F38="","",Date!F38) | G38: =IF(Date!G38="","",Date!G38) | H38: =IF(Date!H38="","",Date!H38) | I38: =IF(Date!I38="","",Date!I38) | J38: =IF(Date!J38="","",Date!J38) | K38: =IF(Date!K38="","",Date!K38) | L38: =IF(Date!L38="","",Date!L38) | M38: =IF(Date!M38="","",Date!M38)
D39: 1인실 | F39: =IF(Date!F39="","",Date!F39) | G39: =IF(Date!G39="","",Date!G39) | H39: =IF(Date!H39="","",Date!H39) | I39: =IF(Date!I39="","",Date!I39) | J39: =IF(Date!J39="","",Date!J39) | K39: =IF(Date!K39="","",Date!K39) | L39: =IF(Date!L39="","",Date!L39) | M39: =IF(Date!M39="","",Date!M39)
D40: 2~3인실 | F40: =IF(Date!F40="","",Date!F40) | G40: =IF(Date!G40="","",Date!G40) | H40: =IF(Date!H40="","",Date!H40) | I40: =IF(Date!I40="","",Date!I40) | J40: =IF(Date!J40="","",Date!J40) | K40: =IF(Date!K40="","",Date!K40) | L40: =IF(Date!L40="","",Date!L40) | M40: =IF(Date!M40="","",Date!M40)
...

Sheet 9칸
A1: =Date!Q1&"님 ("&Date!R1&"세, "&Date!S1&") 보험 보장 분석" -> 님 (세, ) 보험 보장 분석
O2: (만원)
A3: 납입기간 / 만기 | F3: =IF(Date!F3="","",Date!F3) | G3: =IF(Date!G3="","",Date!G3) | H3: =IF(Date!H3="","",Date!H3) | I3: =IF(Date!I3="","",Date!I3) | J3: =IF(Date!J3="","",Date!J3) | K3: =IF(Date!K3="","",Date!K3) | L3: =IF(Date!L3="","",Date!L3) | M3: =IF(Date!M3="","",Date!M3) | N3: =IF(Date!N3="","",Date!N3)
A4: 보험회사 | F4: =IF(Date!F4="","",Date!F4) | G4: =IF(Date!G4="","",Date!G4) | H4: =IF(Date!H4="","",Date!H4) | I4: =IF(Date!I4="","",Date!I4) | J4: =IF(Date!J4="","",Date!J4) | K4: =IF(Date!K4="","",Date!K4) | L4: =IF(Date!L4="","",Date!L4) | M4: =IF(Date!M4="","",Date!M4) | N4: =IF(Date!N4="","",Date!N4)
A5: 상품명 | F5: =IF(Date!F5="","",Date!F5) | G5: =IF(Date!G5="","",Date!G5) | H5: =IF(Date!H5="","",Date!H5) | I5: =IF(Date!I5="","",Date!I5) | J5: =IF(Date!J5="","",Date!J5) | K5: =IF(Date!K5="","",Date!K5) | L5: =IF(Date!L5="","",Date!L5) | M5: =IF(Date!M5="","",Date!M5) | N5: =IF(Date!N5="","",Date!N5)
A6: 가입년도 | F6: =IF(Date!F6="","",Date!F6) | G6: =IF(Date!G6="","",Date!G6) | H6: =IF(Date!H6="","",Date!H6) | I6: =IF(Date!I6="","",Date!I6) | J6: =IF(Date!J6="","",Date!J6) | K6: =IF(Date!K6="","",Date!K6) | L6: =IF(Date!L6="","",Date!L6) | M6: =IF(Date!M6="","",Date!M6) | N6: =IF(Date!N6="","",Date!N6)
A7: 납입보험료 | F7: =IF(Date!F7="","",Date!F7) | G7: =IF(Date!G7="","",Date!G7) | H7: =IF(Date!H7="","",Date!H7) | I7: =IF(Date!I7="","",Date!I7) | J7: =IF(Date!J7="","",Date!J7) | K7: =IF(Date!K7="","",Date!K7) | L7: =IF(Date!L7="","",Date!L7) | M7: =IF(Date!M7="","",Date!M7) | N7: =IF(Date!N7="","",Date!N7)
A8: 사망 | D8: 일반사망 | F8: =IF(Date!F8="","",Date!F8) | G8: =IF(Date!G8="","",Date!G8) | H8: =IF(Date!H8="","",Date!H8) | I8: =IF(Date!I8="","",Date!I8) | J8: =IF(Date!J8="","",Date!J8) | K8: =IF(Date!K8="","",Date!K8) | L8: =IF(Date!L8="","",Date!L8) | M8: =IF(Date!M8="","",Date!M8) | N8: =IF(Date!N8="","",Date!N8)
D9: 상해사망 | F9: =IF(Date!F9="","",Date!F9) | G9: =IF(Date!G9="","",Date!G9) | H9: =IF(Date!H9="","",Date!H9) | I9: =IF(Date!I9="","",Date!I9) | J9: =IF(Date!J9="","",Date!J9) | K9: =IF(Date!K9="","",Date!K9) | L9: =IF(Date!L9="","",Date!L9) | M9: =IF(Date!M9="","",Date!M9) | N9: =IF(Date!N9="","",Date!N9)
D10: 질병사망 | F10: =IF(Date!F10="","",Date!F10) | G10: =IF(Date!G10="","",Date!G10) | H10: =IF(Date!H10="","",Date!H10) | I10: =IF(Date!I10="","",Date!I10) | J10: =IF(Date!J10="","",Date!J10) | K10: =IF(Date!K10="","",Date!K10) | L10: =IF(Date!L10="","",Date!L10) | M10: =IF(Date!M10="","",Date!M10) | N10: =IF(Date!N10="","",Date!N10)
A11: 후유 장해 | D11: 상해 3%~ | F11: =IF(Date!F11="","",Date!F11) | G11: =IF(Date!G11="","",Date!G11) | H11: =IF(Date!H11="","",Date!H11) | I11: =IF(Date!I11="","",Date!I11) | J11: =IF(Date!J11="","",Date!J11) | K11: =IF(Date!K11="","",Date!K11) | L11: =IF(Date!L11="","",Date!L11) | M11: =IF(Date!M11="","",Date!M11) | N11: =IF(Date!N11="","",Date!N11)
D12: 질병 3%~ | F12: =IF(Date!F12="","",Date!F12) | G12: =IF(Date!G12="","",Date!G12) | H12: =IF(Date!H12="","",Date!H12) | I12: =IF(Date!I12="","",Date!I12) | J12: =IF(Date!J12="","",Date!J12) | K12: =IF(Date!K12="","",Date!K12) | L12: =IF(Date!L12="","",Date!L12) | M12: =IF(Date!M12="","",Date!M12) | N12: =IF(Date!N12="","",Date!N12)
A13: 3대 진단 · 수술 | C13: 암 | D13: 고액암 | F13: =IF(Date!F13="","",Date!F13) | G13: =IF(Date!G13="","",Date!G13) | H13: =IF(Date!H13="","",Date!H13) | I13: =IF(Date!I13="","",Date!I13) | J13: =IF(Date!J13="","",Date!J13) | K13: =IF(Date!K13="","",Date!K13) | L13: =IF(Date!L13="","",Date!L13) | M13: =IF(Date!M13="","",Date!M13) | N13: =IF(Date!N13="","",Date!N13)
D14: 일반암 | F14: =IF(Date!F14="","",Date!F14) | G14: =IF(Date!G14="","",Date!G14) | H14: =IF(Date!H14="","",Date!H14) | I14: =IF(Date!I14="","",Date!I14) | J14: =IF(Date!J14="","",Date!J14) | K14: =IF(Date!K14="","",Date!K14) | L14: =IF(Date!L14="","",Date!L14) | M14: =IF(Date!M14="","",Date!M14) | N14: =IF(Date!N14="","",Date!N14)
D15: 유사암(갑,기,경,제) | F15: =IF(Date!F15="","",Date!F15) | G15: =IF(Date!G15="","",Date!G15) | H15: =IF(Date!H15="","",Date!H15) | I15: =IF(Date!I15="","",Date!I15) | J15: =IF(Date!J15="","",Date!J15) | K15: =IF(Date!K15="","",Date!K15) | L15: =IF(Date!L15="","",Date!L15) | M15: =IF(Date!M15="","",Date!M15) | N15: =IF(Date!N15="","",Date!N15)
D16: 재진단암 / 전이암 | F16: =IF(Date!F16="","",Date!F16) | G16: =IF(Date!G16="","",Date!G16) | H16: =IF(Date!H16="","",Date!H16) | I16: =IF(Date!I16="","",Date!I16) | J16: =IF(Date!J16="","",Date!J16) | K16: =IF(Date!K16="","",Date!K16) | L16: =IF(Date!L16="","",Date!L16) | M16: =IF(Date!M16="","",Date!M16) | N16: =IF(Date!N16="","",Date!N16)
D17: 항암 방사선 / 약물 | F17: =IF(Date!F17="","",Date!F17) | G17: =IF(Date!G17="","",Date!G17) | H17: =IF(Date!H17="","",Date!H17) | I17: =IF(Date!I17="","",Date!I17) | J17: =IF(Date!J17="","",Date!J17) | K17: =IF(Date!K17="","",Date!K17) | L17: =IF(Date!L17="","",Date!L17) | M17: =IF(Date!M17="","",Date!M17) | N17: =IF(Date!N17="","",Date!N17)
D18: 암수술비 | F18: =IF(Date!F18="","",Date!F18) | G18: =IF(Date!G18="","",Date!G18) | H18: =IF(Date!H18="","",Date!H18) | I18: =IF(Date!I18="","",Date!I18) | J18: =IF(Date!J18="","",Date!J18) | K18: =IF(Date!K18="","",Date!K18) | L18: =IF(Date!L18="","",Date!L18) | M18: =IF(Date!M18="","",Date!M18) | N18: =IF(Date!N18="","",Date!N18)
D19: 암중환자 | F19: =IF(Date!F19="","",Date!F19) | G19: =IF(Date!G19="","",Date!G19) | H19: =IF(Date!H19="","",Date!H19) | I19: =IF(Date!I19="","",Date!I19) | J19: =IF(Date!J19="","",Date!J19) | K19: =IF(Date!K19="","",Date!K19) | L19: =IF(Date!L19="","",Date!L19) | M19: =IF(Date!M19="","",Date!M19) | N19: =IF(Date!N19="","",Date!N19)
D20: 표적항암 / 카티 | F20: =IF(Date!F20="","",Date!F20) | G20: =IF(Date!G20="","",Date!G20) | H20: =IF(Date!H20="","",Date!H20) | I20: =IF(Date!I20="","",Date!I20) | J20: =IF(Date!J20="","",Date!J20) | K20: =IF(Date!K20="","",Date!K20) | L20: =IF(Date!L20="","",Date!L20) | M20: =IF(Date!M20="","",Date!M20) | N20: =IF(Date!N20="","",Date!N20)
D21: 암특정치료비 | F21: =IF(Date!F21="","",Date!F21) | G21: =IF(Date!G21="","",Date!G21) | H21: =IF(Date!H21="","",Date!H21) | I21: =IF(Date!I21="","",Date!I21) | J21: =IF(Date!J21="","",Date!J21) | K21: =IF(Date!K21="","",Date!K21) | L21: =IF(Date!L21="","",Date!L21) | M21: =IF(Date!M21="","",Date!M21) | N21: =IF(Date!N21="","",Date!N21)
C22: 뇌 | D22: 뇌경색 / 뇌출혈 진단 | F22: =IF(Date!F22="","",Date!F22) | G22: =IF(Date!G22="","",Date!G22) | H22: =IF(Date!H22="","",Date!H22) | I22: =IF(Date!I22="","",Date!I22) | J22: =IF(Date!J22="","",Date!J22) | K22: =IF(Date!K22="","",Date!K22) | L22: =IF(Date!L22="","",Date!L22) | M22: =IF(Date!M22="","",Date!M22) | N22: =IF(Date!N22="","",Date!N22)
D23: 뇌졸중 진단 | F23: =IF(Date!F23="","",Date!F23) | G23: =IF(Date!G23="","",Date!G23) | H23: =IF(Date!H23="","",Date!H23) | I23: =IF(Date!I23="","",Date!I23) | J23: =IF(Date!J23="","",Date!J23) | K23: =IF(Date!K23="","",Date!K23) | L23: =IF(Date!L23="","",Date!L23) | M23: =IF(Date!M23="","",Date!M23) | N23: =IF(Date!N23="","",Date!N23)
D24: 뇌혈관 진단 | F24: =IF(Date!F24="","",Date!F24) | G24: =IF(Date!G24="","",Date!G24) | H24: =IF(Date!H24="","",Date!H24) | I24: =IF(Date!I24="","",Date!I24) | J24: =IF(Date!J24="","",Date!J24) | K24: =IF(Date!K24="","",Date!K24) | L24: =IF(Date!L24="","",Date!L24) | M24: =IF(Date!M24="","",Date!M24) | N24: =IF(Date!N24="","",Date!N24)
D25: 뇌혈관 수술 | F25: =IF(Date!F25="","",Date!F25) | G25: =IF(Date!G25="","",Date!G25) | H25: =IF(Date!H25="","",Date!H25) | I25: =IF(Date!I25="","",Date!I25) | J25: =IF(Date!J25="","",Date!J25) | K25: =IF(Date!K25="","",Date!K25) | L25: =IF(Date!L25="","",Date!L25) | M25: =IF(Date!M25="","",Date!M25) | N25: =IF(Date!N25="","",Date!N25)
C26: 심장 | D26: 급성심근경색 진단 | F26: =IF(Date!F26="","",Date!F26) | G26: =IF(Date!G26="","",Date!G26) | H26: =IF(Date!H26="","",Date!H26) | I26: =IF(Date!I26="","",Date!I26) | J26: =IF(Date!J26="","",Date!J26) | K26: =IF(Date!K26="","",Date!K26) | L26: =IF(Date!L26="","",Date!L26) | M26: =IF(Date!M26="","",Date!M26) | N26: =IF(Date!N26="","",Date!N26)
